Workbook

Sheet 启始页
G6: 欢迎使用
G7: Excel《盖洛普优势识别器》测试系统
A11: 《盖洛普优势识别器2.0》是年中国青年出版社出版的图书，作者是汤姆·拉思。
A12: 为了帮助人们发现自身优势，1998年，优势心理学之父唐纳德克利夫顿博士（1924-2003）与本书作者汤姆拉思及盖洛普科学家团队研发了一项科学的优势测量工具——优势识别器，并将这项独一无二的测量工具纳入到了管理类畅销书《现在，发现你的优势》（中国青年出版社出版）中。此书位列畅销书榜长达5年，且引发了一场全球大讨论。
A13: 2007年，基于对上百万份优势识别器测试结果的分析，盖洛普科学家团队改良并开发出全新版测试——优势识别器2.0。基于50多年的研究，这个测量工具已经帮助成百上千万人发现并发挥他们的天赋优势。
A14: 经过测试，认识您的优势，帮助你在接下来的一周、一个月、一年……时间里发挥自身优势。
K18: 进入测试>>>>>
G23: 更多测试题>>>>

Sheet 首页
B1: 盖洛普优势识别器 | AI1: 亲和 | AK1: 亲和力强的人情商高，能考虑各种情境下人们的感受，并说出恰当的让人舒服的话。
AI2: 诚实 | AK2: 诚实主题较强的人在压力下能保持诚实，但创造力不够强。
B3: 答题说明： | C3: 测试题共有 180 组题，每组有 A / B 两个选择，须在一个小时内答完。 | AI3: 成就 | AK3: 成就主题较强的人大都精力充沛，锲而不舍。他们乐于忙忙碌碌并有所作为。
C4: 1、 | D4: 如果特别同意 A 题请在答题表 A 处填 3，比较同意填 2； | AI4: 行动 | AK4: 行动主题较强的人能够将想法付诸行动。他们往往缺乏耐心。
C5: 2、 | D5: 如果特别同意 B 题请在答题表 B 处填 3，比较同意填 2； | AI5: 适应 | AK5: 适应性强的人倾向于“随大流”。他们活在“当前”，接受现实，随遇而安。
C6: 3、 | D6: 每组只能选一个答案，如果答案介于两者之间，在居中栏填 1。 | AI6: 分析 | AK6: 分析能力强的人喜欢探究事物的来龙去脉。他们有能力思考可能影响局面的诸多因素。
B7: 测算结果： | C7: 见结果页的测试结果，得分排序前五名的主题，就是你最主要的优势。 | AI7: 统筹 | AK7: 统筹力强的人兼具组织能力及确保组织成功的灵活性。他们善于合理安排现有资源以实现最大功效。
AI8: 信仰 | AK8: 有强烈信仰的人必定拥有某种经久不变的核心价值观，并由此形成明确的生活目标。
AI9: 统率 | AK9: 统率力强的人有大将风度。他们运筹帷幄，指挥若定。
D10: 进入测试>>>>> | AI10: 沟通 | AK10: 沟通能力强的人善于将想法付诸言辞，他们是极佳的交谈者和生动的讲解者。
AI11: 竞争 | AK11: 竞争性强的人参照他人的表现来衡量自身的进步。他们力争第一，陶醉于竞争的喜悦中。
AI12: 关联 | AK12: 关联主题较强的人深信世间万物都彼此关联。没有巧合，凡事必有成因。
AI13: 回顾 | AK13: 回顾主题较强的人喜欢追溯从前。他们通过揣摩过去来了解当前。

Sheet 测试题
A1: 答题说明： | B1: 测试题共有 180 组题，每组有 A / B 两个选择，须在一个小时内答完。
A2: 1 | B2: 如果特别同意 A 题请在答题表 A 处填 3，比较同意填 2；
A3: 2 | B3: 如果特别同意 B 题请在答题表 B 处填 3，比较同意填 2；
A4: 3 | B4: 每组只能选一个答案，如果答案介于两者之间，在居中栏填 1。 | D4: 注：A、B、居中三个选项只填其一。
A5: No. | B5: A 组问题 | C5: B 组问题 | D5: 答题表
D6: A | E6: 居中 | F6: B | H6: =SUM(H7:H186) -> 180
A7: 1 | B7: 我乐于助人； | C7: 我喜欢把东西拆开，了解其工作原理和运作的奥妙 | F7: 2 | G7: =IF(OR(AND(D7>0,E7>0),AND(D7>0,F7>0),AND(E7>0,F7>0)),"重复！","") | H7: =IF(AND(D7="",E7="",F7=""),"",1) -> 1
A8: =A7+1 -> 2 | B8: 我喜欢与关注未来的人交往； | C8: 我喜欢和历史学家交往 | D8: 2 | G8: =IF(OR(AND(D8>0,E8>0),AND(D8>0,F8>0),AND(E8>0,F8>0)),"重复！","") | H8: =IF(AND(D8="",E8="",F8=""),"",1) -> 1
A9: =A8+1 -> 3 | B9: 我想要每个人都喜欢我； | C9: 我想要人们崇拜我 | F9: 2 | G9: =IF(OR(AND(D9>0,E9>0),AND(D9>0,F9>0),AND(E9>0,F9>0)),"重复！","") | H9: =IF(AND(D9="",E9="",F9=""),"",1) -> 1
A10: =A9+1 -> 4 | B10: 我力争第一； | C10: 我重在参与 | F10: 2 | G10: =IF(OR(AND(D10>0,E10>0),AND(D10>0,F10>0),AND(E10>0,F10>0)),"重复！","") | H10: =IF(AND(D10="",E10="",F10=""),"",1) -> 1
A11: =A10+1 -> 5 | B11: 我一贯努力工作； | C11: 我做事进展较慢，但确保成效 | D11: 2 | G11: =IF(OR(AND(D11>0,E11>0),AND(D11>0,F11>0),AND(E11>0,F11>0)),"重复！","") | H11: =IF(AND(D11="",E11="",F11=""),"",1) -> 1
A12: =A11+1 -> 6 | B12: 我思考自身的长处； | C12: 我思考有待改进之处 | F12: 2 | G12: =IF(OR(AND(D12>0,E12>0),AND(D12>0,F12>0),AND(E12>0,F12>0)),"重复！","") | H12: =IF(AND(D12="",E12="",F12=""),"",1) -> 1
A13: =A12+1 -> 7 | B13: 我是一个偏重情感的人； | C13: 我是一个偏重理智的人 | F13: 2 | G13: =IF(OR(AND(D13>0,E13>0),AND(D13>0,F13>0),AND(E13>0,F13>0)),"重复！","") | H13: =IF(AND(D13="",E13="",F13=""),"",1) -> 1
A14: =A13+1 -> 8 | B14: 我了解别人的个性特点； | C14: 我能够接受各种类型的人 | F14: 2 | G14: =IF(OR(AND(D14>0,E14>0),AND(D14>0,F14>0),AND(E14>0,F14>0)),"重复！","") | H14: =IF(AND(D14="",E14="",F14=""),"",1) -> 1
A15: =A14+1 -> 9 | B15: 主动与人交谈使我为难； | C15: 与陌生人攀谈使我兴奋 | F15: 2 | G15: =IF(OR(AND(D15>0,E15>0),AND(D15>0,F15>0),AND(E15>0,F15>0)),"重复！","") | H15: =IF(AND(D15="",E15="",F15=""),"",1) -> 1
A16: =A15+1 -> 10 | B16: 我对生活感觉极好； | C16: 我认为我自己很能干 | F16: 3 | G16: =IF(OR(AND(D16>0,E16>0),AND(D16>0,F16>0),AND(E16>0,F16>0)),"重复！","") | H16: =IF(AND(D16="",E16="",F16=""),"",1) -> 1
A17: =A16+1 -> 11 | B17: 我喜欢与人合作； | C17: 我喜欢个人奋斗 | F17: 2 | G17: =IF(OR(AND(D17>0,E17>0),AND(D17>0,F17>0),AND(E17>0,F17>0)),"重复！","") | H17: =IF(AND(D17="",E17="",F17=""),"",1) -> 1
A18: =A17+1 -> 12 | B18: 我能使别人有成就感； | C18: 我能使别人感到我对他们很重要 | F18: 2 | G18: =IF(OR(AND(D18>0,E18>0),AND(D18>0,F18>0),AND(E18>0,F18>0)),"重复！","") | H18: =IF(AND(D18="",E18="",F18=""),"",1) -> 1
A19: =A18+1 -> 13 | B19: 我按照自己的世界观去生活； | C19: 我按照自己的理想去生活 | D19: 3 | G19: =IF(OR(AND(D19>0,E19>0),AND(D19>0,F19>0),AND(E19>0,F19>0)),"重复！","") | H19: =IF(AND(D19="",E19="",F19=""),"",1) -> 1
A20: =A19+1 -> 14 | B20: 成为他人的知己使我满足； | C20: 我希望成为他人的领导 | D20: 2 | G20: =IF(OR(AND(D20>0,E20>0),AND(D20>0,F20>0),AND(E20>0,F20>0)),"重复！","") | H20: =IF(AND(D20="",E20="",F20=""),"",1) -> 1
A21: =A20+1 -> 15 | B21: 我不在意别人对我的所作所为怎么看，我做对自己有利的事； | C21: 我始终清楚别人对我的看法 | D21: 2 | G21: =IF(OR(AND(D21>0,E21>0),AND(D21>0,F21>0),AND(E21>0,F21>0)),"重复！","") | H21: =IF(AND(D21="",E21="",F21=""),"",1) -> 1
A22: =A21+1 -> 16 | B22: 我致力于发展； | C22: 我信守自己的价值观 | D22: 3 | G22: =IF(OR(AND(D22>0,E22>0),AND(D22>0,F22>0),AND(E22>0,F22>0)),"重复！","") | H22: =IF(AND(D22="",E22="",F22=""),"",1) -> 1
A23: =A22+1 -> 17 | B23: 我要自己的生活保持平衡； | C23: 我希望我的家庭过最好的生活 | D23: 3 | G23: =IF(OR(AND(D23>0,E23>0),AND(D23>0,F23>0),AND(E23>0,F23>0)),"重复！","") | H23: =IF(AND(D23="",E23="",F23=""),"",1) -> 1
A24: =A23+1 -> 18 | B24: 我每天多次谈到自己对未来的展望； | C24: 我愿腾出时间思考未来 | F24: 3 | G24: =IF(OR(AND(D24>0,E24>0),AND(D24>0,F24>0),AND(E24>0,F24>0)),"重复！","") | H24: =IF(AND(D24="",E24="",F24=""),"",1) -> 1
A25: =A24+1 -> 19 | B25: 我能够使别人兴奋起来； | C25: 我能够使别人平静下来 | F25: 2 | G25: =IF(OR(AND(D25>0,E25>0),AND(D25>0,F25>0),AND(E25>0,F25>0)),"重复！","") | H25: =IF(AND(D25="",E25="",F25=""),"",1) -> 1
A26: =A25+1 -> 20 | B26: 我一旦作出决定就必须付诸行动； | C26: 我在行动之前需要确认自己行动无误 | F26: 2 | G26: =IF(OR(AND(D26>0,E26>0),AND(D26>0,F26>0),AND(E26>0,F26>0)),"重复！","") | H26: =IF(AND(D26="",E26="",F26=""),"",1) -> 1
A27: =A26+1 -> 21 | B27: 我比大多数人更加专心去做要完成的事； | C27: 我统观全局顺其自然 | D27: 3 | G27: =IF(OR(AND(D27>0,E27>0),AND(D27>0,F27>0),AND(E27>0,F27>0)),"重复！","") | H27: =IF(AND(D27="",E27="",F27=""),"",1) -> 1
A28: =A27+1 -> 22 | B28: 我认为世上没有巧合，一切都事出有因； | C28: 对我来说巧合指运气、机遇、侥幸、偶然 | F28: 3 | G28: =IF(OR(AND(D28>0,E28>0),AND(D28>0,F28>0),AND(E28>0,F28>0)),"重复！","") | H28: =IF(AND(D28="",E28="",F28=""),"",1) -> 1
A29: =A28+1 -> 23 | B29: 我善于交谈； | C29: 我善于倾听 | D29: 2 | G29: =IF(OR(AND(D29>0,E29>0),AND(D29>0,F29>0),AND(E29>0,F29>0)),"重复！","") | H29: =IF(AND(D29="",E29="",F29=""),"",1) -> 1
A30: =A29+1 -> 24 | B30: 我喜欢表扬别人； | C30: 我喜欢受到表扬 | F30: 3 | G30: =IF(OR(AND(D30>0,E30>0),AND(D30>0,F30>0),AND(E30>0,F30>0)),"重复！","") | H30: =IF(AND(D30="",E30="",F30=""),"",1) -> 1
A31: =A30+1 -> 25 | B31: 我喜欢竞赛； | C31: 我喜欢工作 | E31: 1 | G31: =IF(OR(AND(D31>0,E31>0),AND(D31>0,F31>0),AND(E31>0,F31>0)),"重复！","") | H31: =IF(AND(D31="",E31="",F31=""),"",1) -> 1
A32: =A31+1 -> 26 | B32: 我思考问题脚踏实地，善于借助专家寻找正确答案；善于借助专家寻找正确答案； | C32: 我思考问题善于创造，且有战略眼光，对规律和问题一目了然 | F32: 3 | G32: =IF(OR(AND(D32>0,E32>0),AND(D32>0,F32>0),AND(E32>0,F32>0)),"重复！","") | H32: =IF(AND(D32="",E32="",F32=""),"",1) -> 1
A33: =A32+1 -> 27 | B33: 我充满活力，满怀喜悦和欢乐； | C33: 我了解影响形势的所有因素 | F33: 2 | G33: =IF(OR(AND(D33>0,E33>0),AND(D33>0,F33>0),AND(E33>0,F33>0)),"重复！","") | H33: =IF(AND(D33="",E33="",F33=""),"",1) -> 1
A34: =A33+1 -> 28 | B34: 我想成为一家大公司的总裁； | C34: 我为别人牵线搭桥 | F34: 2 | G34: =IF(OR(AND(D34>0,E34>0),AND(D34>0,F34>0),AND(E34>0,F34>0)),"重复！","") | H34: =IF(AND(D34="",E34="",F34=""),"",1) -> 1
A35: =A34+1 -> 29 | B35: 我有时会威逼别人； | C35: 我在大人物面前感到渺小 | E35: 1 | G35: =IF(OR(AND(D35>0,E35>0),AND(D35>0,F35>0),AND(E35>0,F35>0)),"重复！","") | H35: =IF(AND(D35="",E35="",F35=""),"",1) -> 1
A36: =A35+1 -> 30 | B36: 我能设身处地为别着想； | C36: 我能够爱别人，爱所有的人 | D36: 2 | G36: =IF(OR(AND(D36>0,E36>0),AND(D36>0,F36>0),AND(E36>0,F36>0)),"重复！","") | H36: =IF(AND(D36="",E36="",F36=""),"",1) -> 1
A37: =A36+1 -> 31 | B37: 我推动别人成功； | C37: 我使别人快乐 | D37: 2 | G37: =IF(OR(AND(D37>0,E37>0),AND(D37>0,F37>0),AND(E37>0,F37>0)),"重复！","") | H37: =IF(AND(D37="",E37="",F37=""),"",1) -> 1
A38: =A37+1 -> 32 | B38: 我是一个无忧无虑的人； | C38: 我比我的朋友、同事更成熟 | F38: 3 | G38: =IF(OR(AND(D38>0,E38>0),AND(D38>0,F38>0),AND(E38>0,F38>0)),"重复！","") | H38: =IF(AND(D38="",E38="",F38=""),"",1) -> 1
A39: =A38+1 -> 33 | B39: 我尽量与别人一起做事； | C39: 我喜欢为别人张罗 | E39: 1 | G39: =IF(OR(AND(D39>0,E39>0),AND(D39>0,F39>0),AND(E39>0,F39>0)),"重复！","") | H39: =IF(AND(D39="",E39="",F39=""),"",1) -> 1
A40: =A39+1 -> 34 | B40: 通过研究我的历史我可以预测未来； | C40: 我的过去与我的未来无关 | D40: 2 | G40: =IF(OR(AND(D40>0,E40>0),AND(D40>0,F40>0),AND(E40>0,F40>0)),"重复！","") | H40: =IF(AND(D40="",E40="",F40=""),"",1) -> 1
...

Sheet 结
B2: 欢迎使用Excel《盖洛普优势识别器》测试系统 | O2: 测试结果 | AP2: 亲和 | AR2: 亲和力强的人情商高，能考虑各种情境下人们的感受，并说出恰当的让人舒服的话。
C4: 测试结果： | O4: NO | P4: 排名 | Q4: 优势 | R4: 得分 | AP4: 诚实 | AR4: 诚实主题较强的人在压力下能保持诚实，但创造力不够强。
C5: 答题的过程中以下各项优势均随着答题情况不断变化， 答题完成后的排序就是您性格优势的排列顺序。
C7: NO | D7: 优势 | E7: 得分 | F7: NO | G7: 优势 | H7: 得分 | O7: 1 | P7: =RANK(R7,$R$7:$R$58,0)+S7 -> 10 | Q7: =sheet1!E4 -> 成就 | R7: =sheet1!E3 -> 1.4210526 | S7: =COUNTIF(R$7:R$58,R7)-COUNTIF(R$7:R7,R7) -> 0 | AP7: 成就 | AR7: 成就主题较强的人大都精力充沛，锲而不舍。他们乐于忙忙碌碌并有所作为。
C8: 1 | D8: =INDEX(Q:Q,MATCH(C8,P:P,0)) -> 战略 | E8: =INDEX(R:R,MATCH(C8,P:P,0)) -> 2.25 | F8: 18 | G8: =INDEX(Q:Q,MATCH(F8,P:P,0)) -> 个别 | H8: =INDEX(R:R,MATCH(F8,P:P,0)) -> 1 | O8: 2 | P8: =RANK(R8,$R$7:$R$58,0)+S8 -> 32 | Q8: =sheet1!F4 -> 行动 | R8: =sheet1!F3 -> 0.55555556 | S8: =COUNTIF(R$7:R$58,R8)-COUNTIF(R$7:R8,R8) -> 0 | AP8: 行动 | AR8: 行动主题较强的人能够将想法付诸行动。他们往往缺乏耐心。
C9: 2 | D9: =INDEX(Q:Q,MATCH(C9,P:P,0)) -> 思维 | E9: =INDEX(R:R,MATCH(C9,P:P,0)) -> 2.2 | F9: 19 | G9: =INDEX(Q:Q,MATCH(F9,P:P,0)) -> 纪律 | H9: =INDEX(R:R,MATCH(F9,P:P,0)) -> 1 | O9: 3 | P9: =RANK(R9,$R$7:$R$58,0)+S9 -> 21 | Q9: =sheet1!G4 -> 适应 | R9: =sheet1!G3 -> 0.94444444 | S9: =COUNTIF(R$7:R$58,R9)-COUNTIF(R$7:R9,R9) -> 0 | AP9: 适应 | AR9: 适应性强的人倾向于“随大流”。他们活在“当前”，接受现实，随遇而安。
C10: 3 | D10: =INDEX(Q:Q,MATCH(C10,P:P,0)) -> 理念 | E10: =INDEX(R:R,MATCH(C10,P:P,0)) -> 2.1666667 | F10: 20 | G10: =INDEX(Q:Q,MATCH(F10,P:P,0)) -> 竞争 | H10: =INDEX(R:R,MATCH(F10,P:P,0)) -> 1 | O10: 4 | P10: =RANK(R10,$R$7:$R$58,0)+S10 -> 8 | Q10: =sheet1!H4 -> 分析 | R10: =sheet1!H3 -> 1.4736842 | S10: =COUNTIF(R$7:R$58,R10)-COUNTIF(R$7:R10,R10) -> 0 | AP10: 分析 | AR10: 分析能力强的人喜欢探究事物的来龙去脉。他们有能力思考可能影响局面的诸多因素。
C11: 4 | D11: =INDEX(Q:Q,MATCH(C11,P:P,0)) -> 学习 | E11: =INDEX(R:R,MATCH(C11,P:P,0)) -> 1.875 | F11: 21 | G11: =INDEX(Q:Q,MATCH(F11,P:P,0)) -> 适应 | H11: =INDEX(R:R,MATCH(F11,P:P,0)) -> 0.94444444 | O11: 5 | P11: =RANK(R11,$R$7:$R$58,0)+S11 -> 7 | Q11: =sheet1!I4 -> 统筹 | R11: =sheet1!I3 -> 1.6666667 | S11: =COUNTIF(R$7:R$58,R11)-COUNTIF(R$7:R11,R11) -> 0 | AP11: 统筹 | AR11: 统筹力强的人兼具组织能力及确保组织成功的灵活性。他们善于合理安排现有资源以实现最大功效。
C12: 5 | D12: =INDEX(Q:Q,MATCH(C12,P:P,0)) -> 前瞻 | E12: =INDEX(R:R,MATCH(C12,P:P,0)) -> 1.75 | F12: 22 | G12: =INDEX(Q:Q,MATCH(F12,P:P,0)) -> 回顾 | H12: =INDEX(R:R,MATCH(F12,P:P,0)) -> 0.93333333 | O12: 6 | P12: =RANK(R12,$R$7:$R$58,0)+S12 -> 15 | Q12: =sheet1!J4 -> 信仰 | R12: =sheet1!J3 -> 1.2352941 | S12: =COUNTIF(R$7:R$58,R12)-COUNTIF(R$7:R12,R12) -> 0 | AP12: 信仰 | AR12: 有强烈信仰的人必定拥有某种经久不变的核心价值观，并由此形成明确的生活目标。
C13: 6 | D13: =INDEX(Q:Q,MATCH(C13,P:P,0)) -> 统率 | E13: =INDEX(R:R,MATCH(C13,P:P,0)) -> 1.7333333 | F13: 23 | G13: =INDEX(Q:Q,MATCH(F13,P:P,0)) -> 完美 | H13: =INDEX(R:R,MATCH(F13,P:P,0)) -> 0.88235294 | O13: 7 | P13: =RANK(R13,$R$7:$R$58,0)+S13 -> 6 | Q13: =sheet1!K4 -> 统率 | R13: =sheet1!K3 -> 1.7333333 | S13: =COUNTIF(R$7:R$58,R13)-COUNTIF(R$7:R13,R13) -> 0 | AP13: 统率 | AR13: 统率力强的人有大将风度。他们运筹帷幄，指挥若定。
C14: 7 | D14: =INDEX(Q:Q,MATCH(C14,P:P,0)) -> 统筹 | E14: =INDEX(R:R,MATCH(C14,P:P,0)) -> 1.6666667 | F14: 24 | G14: =INDEX(Q:Q,MATCH(F14,P:P,0)) -> 搜集 | H14: =INDEX(R:R,MATCH(F14,P:P,0)) -> 0.88235294 | O14: 8 | P14: =RANK(R14,$R$7:$R$58,0)+S14 -> 33 | Q14: =sheet1!L4 -> 沟通 | R14: =sheet1!L3 -> 0.5 | S14: =COUNTIF(R$7:R$58,R14)-COUNTIF(R$7:R14,R14) -> 0 | AP14: 沟通 | AR14: 沟通能力强的人善于将想法付诸言辞，他们是极佳的交谈者和生动的讲解者。
C15: 8 | D15: =INDEX(Q:Q,MATCH(C15,P:P,0)) -> 分析 | E15: =INDEX(R:R,MATCH(C15,P:P,0)) -> 1.4736842 | F15: 25 | G15: =INDEX(Q:Q,MATCH(F15,P:P,0)) -> 公平 | H15: =INDEX(R:R,MATCH(F15,P:P,0)) -> 0.875 | O15: 9 | P15: =RANK(R15,$R$7:$R$58,0)+S15 -> 20 | Q15: =sheet1!M4 -> 竞争 | R15: =sheet1!M3 -> 1 | S15: =COUNTIF(R$7:R$58,R15)-COUNTIF(R$7:R15,R15) -> 2 | AP15: 竞争 | AR15: 竞争性强的人参照他人的表现来衡量自身的进步。他们力争第一，陶醉于竞争的喜悦中。
C16: 9 | D16: =INDEX(Q:Q,MATCH(C16,P:P,0)) -> 排难 | E16: =INDEX(R:R,MATCH(C16,P:P,0)) -> 1.4375 | F16: 26 | G16: =INDEX(Q:Q,MATCH(F16,P:P,0)) -> 体谅 | H16: =INDEX(R:R,MATCH(F16,P:P,0)) -> 0.8 | O16: 10 | P16: =RANK(R16,$R$7:$R$58,0)+S16 -> 31 | Q16: =sheet1!N4 -> 关联 | R16: =sheet1!N3 -> 0.61111111 | S16: =COUNTIF(R$7:R$58,R16)-COUNTIF(R$7:R16,R16) -> 0 | AP16: 关联 | AR16: 关联主题较强的人深信世间万物都彼此关联。没有巧合，凡事必有成因。
C17: 10 | D17: =INDEX(Q:Q,MATCH(C17,P:P,0)) -> 成就 | E17: =INDEX(R:R,MATCH(C17,P:P,0)) -> 1.4210526 | F17: 27 | G17: =INDEX(Q:Q,MATCH(F17,P:P,0)) -> 交往 | H17: =INDEX(R:R,MATCH(F17,P:P,0)) -> 0.75 | O17: 11 | P17: =RANK(R17,$R$7:$R$58,0)+S17 -> 22 | Q17: =sheet1!O4 -> 回顾 | R17: =sheet1!O3 -> 0.93333333 | S17: =COUNTIF(R$7:R$58,R17)-COUNTIF(R$7:R17,R17) -> 0 | AP17: 回顾 | AR17: 回顾主题较强的人喜欢追溯从前。他们通过揣摩过去来了解当前。
C18: 11 | D18: =INDEX(Q:Q,MATCH(C18,P:P,0)) -> 审慎 | E18: =INDEX(R:R,MATCH(C18,P:P,0)) -> 1.4 | F18: 28 | G18: =INDEX(Q:Q,MATCH(F18,P:P,0)) -> 取悦 | H18: =INDEX(R:R,MATCH(F18,P:P,0)) -> 0.6875 | O18: 12 | P18: =RANK(R18,$R$7:$R$58,0)+S18 -> 11 | Q18: =sheet1!P4 -> 审慎 | R18: =sheet1!P3 -> 1.4 | S18: =COUNTIF(R$7:R$58,R18)-COUNTIF(R$7:R18,R18) -> 0 | AP18: 审慎 | AR18: 他们每做一个决定均慎之又慎，并设想所有的困难。
C19: 12 | D19: =INDEX(Q:Q,MATCH(C19,P:P,0)) -> 责任 | E19: =INDEX(R:R,MATCH(C19,P:P,0)) -> 1.375 | F19: 29 | G19: =INDEX(Q:Q,MATCH(F19,P:P,0)) -> 包容 | H19: =INDEX(R:R,MATCH(F19,P:P,0)) -> 0.64705882 | O19: 13 | P19: =RANK(R19,$R$7:$R$58,0)+S19 -> 17 | Q19: =sheet1!Q4 -> 伯乐 | R19: =sheet1!Q3 -> 1.0625 | S19: =COUNTIF(R$7:R$58,R19)-COUNTIF(R$7:R19,R19) -> 0 | AP19: 伯乐 | AR19: 他们善于赏识并发掘他人的潜能。他们能够察觉任何细微的进步，并乐在其中。
C20: 13 | D20: =INDEX(Q:Q,MATCH(C20,P:P,0)) -> 自信 | E20: =INDEX(R:R,MATCH(C20,P:P,0)) -> 1.3529412 | F20: 30 | G20: =INDEX(Q:Q,MATCH(F20,P:P,0)) -> 和谐 | H20: =INDEX(R:R,MATCH(F20,P:P,0)) -> 0.625 | O20: 14 | P20: =RANK(R20,$R$7:$R$58,0)+S20 -> 19 | Q20: =sheet1!R4 -> 纪律 | R20: =sheet1!R3 -> 1 | S20: =COUNTIF(R$7:R$58,R20)-COUNTIF(R$7:R20,R20) -> 1 | AP20: 纪律 | AR20: 纪律性强的人做事井然有序，有章有法。他们建立规程，遵章守纪。
C21: 14 | D21: =INDEX(Q:Q,MATCH(C21,P:P,0)) -> 追求 | E21: =INDEX(R:R,MATCH(C21,P:P,0)) -> 1.2631579 | F21: 31 | G21: =INDEX(Q:Q,MATCH(F21,P:P,0)) -> 关联 | H21: =INDEX(R:R,MATCH(F21,P:P,0)) -> 0.61111111 | O21: 15 | P21: =RANK(R21,$R$7:$R$58,0)+S21 -> 26 | Q21: =sheet1!S4 -> 体谅 | R21: =sheet1!S3 -> 0.8 | S21: =COUNTIF(R$7:R$58,R21)-COUNTIF(R$7:R21,R21) -> 0 | AP21: 体谅 | AR21: 他们能够设身处地地体会他人的情感。
C22: 15 | D22: =INDEX(Q:Q,MATCH(C22,P:P,0)) -> 信仰 | E22: =INDEX(R:R,MATCH(C22,P:P,0)) -> 1.2352941 | F22: 32 | G22: =INDEX(Q:Q,MATCH(F22,P:P,0)) -> 行动 | H22: =INDEX(R:R,MATCH(F22,P:P,0)) -> 0.55555556 | O22: 16 | P22: =RANK(R22,$R$7:$R$58,0)+S22 -> 25 | Q22: =sheet1!T4 -> 公平 | R22: =sheet1!T3 -> 0.875 | S22: =COUNTIF(R$7:R$58,R22)-COUNTIF(R$7:R22,R22) -> 0 | AP22: 公平 | AR22: 公平心强的人深知应平等待人。他们确立并坚持这一准则，即公平地对待每一个人。
C23: 16 | D23: =INDEX(Q:Q,MATCH(C23,P:P,0)) -> 专注 | E23: =INDEX(R:R,MATCH(C23,P:P,0)) -> 1.125 | F23: 33 | G23: =INDEX(Q:Q,MATCH(F23,P:P,0)) -> 沟通 | H23: =INDEX(R:R,MATCH(F23,P:P,0)) -> 0.5 | O23: 17 | P23: =RANK(R23,$R$7:$R$58,0)+S23 -> 16 | Q23: =sheet1!U4 -> 专注 | R23: =sheet1!U3 -> 1.125 | S23: =COUNTIF(R$7:R$58,R23)-COUNTIF(R$7:R23,R23) -> 0 | AP23: 专注 | AR23: 专注力强的人能够确定方向，贯彻始终，及时调整，矢志不渝。他们先确定重点，再着手行动。
C24: 17 | D24: =INDEX(Q:Q,MATCH(C24,P:P,0)) -> 伯乐 | E24: =INDEX(R:R,MATCH(C24,P:P,0)) -> 1.0625 | F24: 34 | G24: =INDEX(Q:Q,MATCH(F24,P:P,0)) -> 积极 | H24: =INDEX(R:R,MATCH(F24,P:P,0)) -> 0.3125 | O24: 18 | P24: =RANK(R24,$R$7:$R$58,0)+S24 -> 5 | Q24: =sheet1!V4 -> 前瞻 | R24: =sheet1!V3 -> 1.75 | S24: =COUNTIF(R$7:R$58,R24)-COUNTIF(R$7:R24,R24) -> 0 | AP24: 前瞻 | AR24: 对于有较强前瞻力的人而言，未来令人心潮澎湃。他们用对未来的憧憬激励周围的人。
A26: =测试题!H6 -> 180 | B26: =IF(A26<180,"","由以上结果可以看出，您的优势为：") -> 由以上结果可以看出，您的优势为：
B27: =IF(A$26<180,"",B46) -> 1 | C27: =IF(B27="","",INDEX(Q:Q,MATCH(B27,P:P,0))) -> 战略 | D27: =IF(B27="","",INDEX(Sheet2!B:B,MATCH(C27,Sheet2!A:A,0))) -> 战略主题较强的人足智多谋。针对不同的方案，能迅速找出相关的模式及结果。
C28: =IF(B27="","",INDEX(Sheet2!B:B,MATCH(C27,Sheet2!A:A,0)+1)) -> 战略主题使你能够透过日常琐碎，寻找前进的捷径。它不是一种可以教授的技能，而是一种与众不同的思维方式，一种独特的世界观。有了这种世界观，当别人被复杂的事物所迷惑时，你却能识别其中的规律。你将规律牢记在心，尝试各种不同的方案，不断问自己“如果发生这种情况会怎样？如果发生那种情况会怎样？”这些不断出现的问题帮助你预防不测。如此你便能够精确判断潜在的障碍。你看清各条路径的走向，就能进行筛选。你筛去死路。你筛去直通屏障的路线。你筛去通往混乱和迷茫的路线。你不断筛选，直到你选定一条路线-这就是你的战略。有了战略武装，你开始出击。这就是你的战略主题的运作模式：“倘若……会怎样？”筛选，出击。
B29: =IF(A$26<180,"",B47) -> 2 | C29: =IF(B29="","",INDEX(Q:Q,MATCH(B29,P:P,0))) -> 思维 | D29: =IF(B29="","",INDEX(Sheet2!B:B,MATCH(C29,Sheet2!A:A,0))) -> 思维能力较强的人的最大特点是长于思考。他们勤于自省，敏于探讨。
C30: =IF(B29="","",INDEX(Sheet2!B:B,MATCH(C29,Sheet2!A:A,0)+1)) -> 你喜欢思考。你喜欢思想活动。你喜欢锻炼你的大脑“肌肉”，把它们四面抻扯。这种对思想活动的需求有可能是专注的，专注的焦点取决于你的其它优势。例如，你可能努力解决一个问题，或酝酿一个创意，或了解另一个人的感受。另一方面，这种思维活动很可能漫无边际。思维的主题并不一定限定你思考的具体内容。它只是说你喜欢思考。你是一个喜欢独处的人，因为这样你才能沉思冥想。你性格内向。在某种意义上，你是自己最好的伴侣，因为你扪心自问，并在自己身上测试答案。当你把自己的实际作为与你所思考的所有想法相比时，你的这种自省可能会使你略为不满。但此种自省也可能导致你关注现实问题，例如当日所发生的事件，或你准备进行的一场谈话。无论它把你引向何方，这种不停的思考是你生活中的一个固定内容。
B31: =IF(A$26<180,"",B48) -> 3 | C31: =IF(B31="","",INDEX(Q:Q,MATCH(B31,P:P,0))) -> 理念 | D31: =IF(B31="","",INDEX(Sheet2!B:B,MATCH(C31,Sheet2!A:A,0))) -> 他们痴迷于各种理念，能够从貌似毫无关联的现象中找出其相互联系。
C32: =IF(B31="","",INDEX(Sheet2!B:B,MATCH(C31,Sheet2!A:A,0)+1)) -> 你为理念而痴迷。什幺是理念？理念就是概念，就是对大部分事件的最合理的解释。当你透过复杂的表层，发现一个精彩而简明的概念，继而解释事物的本质时，你会喜不自胜。理念是一种关联。你的头脑总在寻找关联；因此，当表面截然不同的现象被某个不起眼的纽带联系在一起时，你会感到新奇。一个理念是对习以为常的挑战的全新见解。你乐于将我们熟知的世界转一个圈，让我们从一个陌生但充满新意的角度看它。你喜爱所有这些理念。因为它们深刻。因为它们新颖。因为它们能正本清源。因为它们引发争论。因为它们怪诞。由于所有这些原因，每当你产生一个新理念时，你都为之一振。别人可能视你为锐意创新、标新立异、富于理性或聪明过人。也许这些你都是。谁能说得准呢？你确信无疑的是理念使你激动不已。而大多数日子里，这就足够了。
B33: =IF(A$26<180,"",B49) -> 4 | C33: =IF(B33="","",INDEX(Q:Q,MATCH(B33,P:P,0))) -> 学习 | D33: =IF(B33="","",INDEX(Sheet2!B:B,MATCH(C33,Sheet2!A:A,0))) -> 学习能力强的人有旺盛的求知欲，渴望不断提高自我。尤其令他们激动的，是求知的过程而非结果。
C34: =IF(B33="","",INDEX(Sheet2!B:B,MATCH(C33,Sheet2!A:A,0)+1)) -> 你热爱学习。你最感兴趣的题目取决于你的其它主题和经历。但无论是什幺题目，你总是受到学习过程的吸引。过程，而不是内容或结果，最使你兴奋。从无知到熟练的扎实而执着的进程使你精力倍增。入门的快感；初学者背诵或实践学到的内容；掌握一门新技术而日益增强的信心-这些学习的过程深深吸引着你。你对学习的激情促使你参加各种成人教程-太极拳、外语、钢琴、舞蹈或电脑培训班等等。它使你能在变动无常的环境中应付自如，无论是分配你完成一个应急项目，还是反复要求你在短时间内成为某个新题目的行家。学习主题并不一定意味着你力图成为某个专题的专家，或追求伴随某种专业或学术头衔的荣耀。相比之下，更重要的是学习的“路程”，而不是具体结果。
B35: =IF(A$26<180,"",B50) -> 5 | C35: =IF(B35="","",INDEX(Q:Q,MATCH(B35,P:P,0))) -> 前瞻 | D35: =IF(B35="","",INDEX(Sheet2!B:B,MATCH(C35,Sheet2!A:A,0))) -> 对于有较强前瞻力的人而言，未来令人心潮澎湃。他们用对未来的憧憬激励周围的人。
C36: =IF(B35="","",INDEX(Sheet2!B:B,MATCH(C35,Sheet2!A:A,0)+1)) -> “如果这样，那该多好？”你是个喜欢遥望天际的人。未来使你着迷。未来如同墙壁上的投影，在你眼中维妙维肖。这幅细致入微的图画催你奋进，奔向明天。虽然未来图景的具体内容取决于你的其它优势和兴趣-更好的产品，更好的队伍，更好的生活，或更好的世界-但它将永远给你以灵感。你是一个幻想家，能看到未来的种种可能，并珍视这样的想象。当现实使你一筹莫展，而你周围的人又过于世俗时，你就会唤起对未来的憧憬，继而精力倍增，同时振奋别人。事实上，人们往往期待你描述对未来的种种遐想。他们希望看到一幅画卷，来提高他们的眼界，继而燃起激情。你能为他们描绘这幅画卷。不断实践。字斟句酌。越生动越好。人们将拥抱你所带来的希望。
O37: 19 | P37: =RANK(R37,$R$7:$R$58,0)+S37 -> 30 | Q37: =sheet1!W4 -> 和谐 | R37: =sheet1!W3 -> 0.625 | S37: =COUNTIF(R$7:R$58,R37)-COUNTIF(R$7:R37,R37) -> 0 | AP37: 和谐 | AR37: 和谐主题较强的人渴求协调一致。他们避免冲突，寻求共识。
O44: 20 | P44: =RANK(R44,$R$7:$R$58,0)+S44 -> 3 | Q44: =sheet1!X4 -> 理念 | R44: =sheet1!X3 -> 2.1666667 | S44: =COUNTIF(R$7:R$58,R44)-COUNTIF(R$7:R44,R44) -> 0 | AP44: 理念 | AR44: 他们痴迷于各种理念，能够从貌似毫无关联的现象中找出其相互联系。
B45: 34 项 优 势 描 述 | O45: 21 | P45: =RANK(R45,$R$7:$R$58,0)+S45 -> 29 | Q45: =sheet1!Y4 -> 包容 | R45: =sheet1!Y3 -> 0.64705882 | S45: =COUNTIF(R$7:R$58,R45)-COUNTIF(R$7:R45,R45) -> 0 | AP45: 包容 | AR45: 包容力强的人善于接纳人。他们关心那些被忽略的人们，并让他们溶入集体。
B46: 1 | C46: =INDEX(Q:Q,MATCH(B46,P:P,0)) -> 战略 | D46: =INDEX(AR:AR,MATCH(C46,AP:AP,0)) -> 战略主题较强的人足智多谋。针对不同的方案，能迅速找出相关的模式及结果。 | O46: 22 | P46: =RANK(R46,$R$7:$R$58,0)+S46 -> 18 | Q46: =sheet1!Z4 -> 个别 | R46: =sheet1!Z3 -> 1 | S46: =COUNTIF(R$7:R$58,R46)-COUNTIF(R$7:R46,R46) -> 0 | AP46: 个别 | AR46: 个别主题较强的人对每个人的与众不同之处兴趣盎然。他们善于琢磨如何将个性迥异的人组合在一起，创造出最大成效。
B47: 2 | C47: =INDEX(Q:Q,MATCH(B47,P:P,0)) -> 思维 | D47: =INDEX(AR:AR,MATCH(C47,AP:AP,0)) -> 思维能力较强的人的最大特点是长于思考。他们勤于自省，敏于探讨。 | O47: 23 | P47: =RANK(R47,$R$7:$R$58,0)+S47 -> 24 | Q47: =sheet1!AA4 -> 搜集 | R47: =sheet1!AA3 -> 0.88235294 | S47: =COUNTIF(R$7:R$58,R47)-COUNTIF(R$7:R47,R47) -> 1 | AP47: 搜集 | AR47: 搜集主题较强的人充满好奇。他们通常喜欢搜集、整理各种各样的信息。
B48: 3 | C48: =INDEX(Q:Q,MATCH(B48,P:P,0)) -> 理念 | D48: =INDEX(AR:AR,MATCH(C48,AP:AP,0)) -> 他们痴迷于各种理念，能够从貌似毫无关联的现象中找出其相互联系。 | O48: 24 | P48: =RANK(R48,$R$7:$R$58,0)+S48 -> 2 | Q48: =sheet1!AB4 -> 思维 | R48: =sheet1!AB3 -> 2.2 | S48: =COUNTIF(R$7:R$58,R48)-COUNTIF(R$7:R48,R48) -> 0 | AP48: 思维 | AR48: 思维能力较强的人的最大特点是长于思考。他们勤于自省，敏于探讨。
B49: 4 | C49: =INDEX(Q:Q,MATCH(B49,P:P,0)) -> 学习 | D49: =INDEX(AR:AR,MATCH(C49,AP:AP,0)) -> 学习能力强的人有旺盛的求知欲，渴望不断提高自我。尤其令他们激动的，是求知的过程而非结果。 | O49: 25 | P49: =RANK(R49,$R$7:$R$58,0)+S49 -> 4 | Q49: =sheet1!AC4 -> 学习 | R49: =sheet1!AC3 -> 1.875 | S49: =COUNTIF(R$7:R$58,R49)-COUNTIF(R$7:R49,R49) -> 0 | AP49: 学习 | AR49: 学习能力强的人有旺盛的求知欲，渴望不断提高自我。尤其令他们激动的，是求知的过程而非结果。
B50: 5 | C50: =INDEX(Q:Q,MATCH(B50,P:P,0)) -> 前瞻 | D50: =INDEX(AR:AR,MATCH(C50,AP:AP,0)) -> 对于有较强前瞻力的人而言，未来令人心潮澎湃。他们用对未来的憧憬激励周围的人。 | O50: 26 | P50: =RANK(R50,$R$7:$R$58,0)+S50 -> 23 | Q50: =sheet1!AD4 -> 完美 | R50: =sheet1!AD3 -> 0.88235294 | S50: =COUNTIF(R$7:R$58,R50)-COUNTIF(R$7:R50,R50) -> 0 | AP50: 完美 | AR50: 完美主题较强的人专注于激励个人和团体追求卓越。他们相信强中自有强中手。
...

Sheet sheet1
E2: 19 | F2: 18 | G2: 18 | H2: 19 | I2: 15 | J2: 17 | K2: 15 | L2: 16 | M2: 15 | N2: 18 | O2: 15 | P2: 20 | Q2: 16 | R2: 17 | S2: 15 | T2: 16 | U2: 16 | V2: 16 | W2: 16 | X2: 18 | Y2: 17 | Z2: 16 | AA2: 17 | AB2: 20 | AC2: 16 | AD2: 17 | AE2: 16 | AF2: 16 | AG2: 16 | AH2: 16 | AI2: 17 | AJ2: 19 | AK2: 20 | AL2: 16
A3: % | D3: % | E3: =SUM(E5:E184)/E2 -> 1.4210526 | F3: =SUM(F5:F184)/F2 -> 0.55555556 | G3: =SUM(G5:G184)/G2 -> 0.94444444 | H3: =SUM(H5:H184)/H2 -> 1.4736842 | I3: =SUM(I5:I184)/I2 -> 1.6666667 | J3: =SUM(J5:J184)/J2 -> 1.2352941 | K3: =SUM(K5:K184)/K2 -> 1.7333333 | L3: =SUM(L5:L184)/L2 -> 0.5 | ... AL3: =SUM(AL5:AL184)/AL2 -> 0.6875
A4: NO | B4: A | C4: 居中 | D4: B | E4: 成就 | F4: 行动 | G4: 适应 | H4: 分析 | I4: 统筹 | J4: 信仰 | K4: 统率 | L4: 沟通 | M4: 竞争 | N4: 关联 | O4: 回顾 | P4: 审慎 | Q4: 伯乐 | R4: 纪律 | S4: 体谅 | T4: 公平 | U4: 专注 | V4: 前瞻 | W4: 和谐 | X4: 理念 | Y4: 包容 | Z4: 个别 | AA4: 搜集 | AB4: 思维 | AC4: 学习 | AD4: 完美 | AE4: 积极 | AF4: 交往 | AG4: 责任 | AH4: 排难 | AI4: 自信 | AJ4: 追求 | AK4: 战略 | AL4: 取悦
A5: 1 | B5: =测试题!D7 -> 0 | C5: =测试题!E7 -> 0 | D5: =测试题!F7 -> 2 | H5: =C5+D5 -> 2 | J5: =C5+B5 -> 0 | S5: =C5+B5 -> 0 | AC5: =C5+D5 -> 2 | AF5: =C5+B5 -> 0 | AH5: =C5+B5 -> 0
A6: =A5+1 -> 2 | B6: =测试题!D8 -> 2 | C6: =测试题!E8 -> 0 | D6: =测试题!F8 -> 0 | O6: =+C6+D6 -> 0 | V6: =C6+B6 -> 2
A7: =A6+1 -> 3 | B7: =测试题!D9 -> 0 | C7: =测试题!E9 -> 0 | D7: =测试题!F9 -> 2 | AJ7: =C7+D7 -> 2 | AL7: =C7+B7 -> 0
A8: =A7+1 -> 4 | B8: =测试题!D10 -> 0 | C8: =测试题!E10 -> 0 | D8: =测试题!F10 -> 2 | E8: =C8+B8 -> 0 | M8: =C8+B8 -> 0 | AC8: =C8+D8 -> 2 | AD8: =C8+B8 -> 0
A9: =A8+1 -> 5 | B9: =测试题!D11 -> 2 | C9: =测试题!E11 -> 0 | D9: =测试题!F11 -> 0 | E9: =C9+B9 -> 2 | AG9: =C9+D9 -> 0
A10: =A9+1 -> 6 | B10: =测试题!D12 -> 0 | C10: =测试题!E12 -> 0 | D10: =测试题!F12 -> 2 | AD10: =C10+B10 -> 0 | AJ10: =C10+D10 -> 2
A11: =A10+1 -> 7 | B11: =测试题!D13 -> 0 | C11: =测试题!E13 -> 0 | D11: =测试题!F13 -> 2 | H11: =$C11+$D11 -> 2 | I11: =$C11+$D11 -> 2 | J11: =$C11+$B11 -> 0 | K11: =$C11+$D11 -> 2 | P11: =$C11+$D11 -> 2 | S11: =$C11+$B11 -> 0 | T11: =$C11+$B11 -> 0 | AK11: =$C11+$D11 -> 2 | AL11: =$C11+$B11 -> 0
A12: =A11+1 -> 8 | B12: =测试题!D14 -> 0 | C12: =测试题!E14 -> 0 | D12: =测试题!F14 -> 2 | S12: =$C12+$B12 -> 0 | T12: =$C12+$D12 -> 2 | Y12: =$C12+$D12 -> 2 | Z12: =$C12+$B12 -> 0
A13: =A12+1 -> 9 | B13: =测试题!D15 -> 0 | C13: =测试题!E15 -> 0 | D13: =测试题!F15 -> 2 | P13: =C13+B13 -> 0 | AL13: =C13+D13 -> 2
A14: =A13+1 -> 10 | B14: =测试题!D16 -> 0 | C14: =测试题!E16 -> 0 | D14: =测试题!F16 -> 3 | AE14: =C14+B14 -> 0 | AI14: =C14+D14 -> 3
A15: =A14+1 -> 11 | B15: =测试题!D17 -> 0 | C15: =测试题!E17 -> 0 | D15: =测试题!F17 -> 2 | Y15: =C15+B15 -> 0 | AB15: =C15+D15 -> 2 | AF15: =C15+B15 -> 0 | AI15: =C15+D15 -> 2
A16: =A15+1 -> 12 | B16: =测试题!D18 -> 0 | C16: =测试题!E18 -> 0 | D16: =测试题!F18 -> 2 | K16: =C16+D16 -> 2 | Q16: =C16+B16 -> 0
A17: =A16+1 -> 13 | B17: =测试题!D19 -> 3 | C17: =测试题!E19 -> 0 | D17: =测试题!F19 -> 0 | J17: =C17+B17 -> 3 | AD17: =C17+D17 -> 0
A18: =A17+1 -> 14 | B18: =测试题!D20 -> 2 | C18: =测试题!E20 -> 0 | D18: =测试题!F20 -> 0 | K18: =C18+D18 -> 0 | AF18: =C18+B18 -> 2
A19: =A18+1 -> 15 | B19: =测试题!D21 -> 2 | C19: =测试题!E21 -> 0 | D19: =测试题!F21 -> 0 | K19: =C19+B19 -> 2 | S19: =C19+D19 -> 0
A20: =A19+1 -> 16 | B20: =测试题!D22 -> 3 | C20: =测试题!E22 -> 0 | D20: =测试题!F22 -> 0 | J20: =C20+D20 -> 0 | V20: =C20+B20 -> 3
A21: =A20+1 -> 17 | B21: =测试题!D23 -> 3 | C21: =测试题!E23 -> 0 | D21: =测试题!F23 -> 0 | P21: =C21+B21 -> 3 | AD21: =C21+D21 -> 0 | AJ21: =C21+D21 -> 0
A22: =A21+1 -> 18 | B22: =测试题!D24 -> 0 | C22: =测试题!E24 -> 0 | D22: =测试题!F24 -> 3 | V22: =C22+B22 -> 0 | AJ22: =C22+D22 -> 3 | AK22: =C22+D22 -> 3
A23: =A22+1 -> 19 | B23: =测试题!D25 -> 0 | C23: =测试题!E25 -> 0 | D23: =测试题!F25 -> 2 | W23: =C23+D23 -> 2 | AE23: =C23+B23 -> 0
A24: =A23+1 -> 20 | B24: =测试题!D26 -> 0 | C24: =测试题!E26 -> 0 | D24: =测试题!F26 -> 2 | F24: =C24+B24 -> 0 | P24: =C24+D24 -> 2
A25: =A24+1 -> 21 | B25: =测试题!D27 -> 3 | C25: =测试题!E27 -> 0 | D25: =测试题!F27 -> 0 | G25: =C25+D25 -> 0 | U25: =C25+B25 -> 3
A26: =A25+1 -> 22 | B26: =测试题!D28 -> 0 | C26: =测试题!E28 -> 0 | D26: =测试题!F28 -> 3 | G26: =C26+D26 -> 3 | N26: =C26+B26 -> 0
A27: =A26+1 -> 23 | B27: =测试题!D29 -> 2 | C27: =测试题!E29 -> 0 | D27: =测试题!F29 -> 0 | L27: =C27+B27 -> 2 | S27: =C27+D27 -> 0
A28: =A27+1 -> 24 | B28: =测试题!D30 -> 0 | C28: =测试题!E30 -> 0 | D28: =测试题!F30 -> 3 | E28: =C28+D28 -> 3 | Q28: =C28+B28 -> 0 | AE28: =C28+B28 -> 0 | AJ28: =C28+D28 -> 3 | AL28: =C28+B28 -> 0
A29: =A28+1 -> 25 | B29: =测试题!D31 -> 0 | C29: =测试题!E31 -> 1 | D29: =测试题!F31 -> 0 | M29: =C29+B29 -> 1 | AF29: =C29+D29 -> 1
A30: =A29+1 -> 26 | B30: =测试题!D32 -> 0 | C30: =测试题!E32 -> 0 | D30: =测试题!F32 -> 3 | N30: =C30+B30 -> 0 | X30: =C30+D30 -> 3 | AB30: =C30+D30 -> 3 | AK30: =C30+D30 -> 3
A31: =A30+1 -> 27 | B31: =测试题!D33 -> 0 | C31: =测试题!E33 -> 0 | D31: =测试题!F33 -> 2 | H31: =C31+D31 -> 2 | P31: =C31+B31 -> 0 | AE31: =C31+B31 -> 0
A32: =A31+1 -> 28 | B32: =测试题!D34 -> 0 | C32: =测试题!E34 -> 0 | D32: =测试题!F34 -> 2 | E32: =C32+B32 -> 0 | K32: =C32+B32 -> 0 | Q32: =C32+D32 -> 2 | AJ32: =C32+B32 -> 0
A33: =A32+1 -> 29 | B33: =测试题!D35 -> 0 | C33: =测试题!E35 -> 1 | D33: =测试题!F35 -> 0 | K33: =C33+B33-D33 -> 1 | W33: =C33+D33 -> 1
A34: =A33+1 -> 30 | B34: =测试题!D36 -> 2 | C34: =测试题!E36 -> 0 | D34: =测试题!F36 -> 0 | J34: =C34+D34 -> 0 | S34: =C34+B34 -> 2 | T34: =C34+D34 -> 0 | Z34: =C34+B34 -> 2
A35: =A34+1 -> 31 | B35: =测试题!D37 -> 2 | C35: =测试题!E37 -> 0 | D35: =测试题!F37 -> 0 | Q35: =C35+B35 -> 2 | AE35: =C35+D35 -> 0
A36: =A35+1 -> 32 | B36: =测试题!D38 -> 0 | C36: =测试题!E38 -> 0 | D36: =测试题!F38 -> 3 | I36: =C36+D36 -> 3 | P36: =C36+D36 -> 3 | AE36: =C36+B36 -> 0 | AK36: =C36+D36 -> 3
A37: =A36+1 -> 33 | B37: =测试题!D39 -> 0 | C37: =测试题!E39 -> 1 | D37: =测试题!F39 -> 0 | I37: =C37+D37 -> 1 | Q37: =C37+D37 -> 1 | W37: =C37+B37 -> 1 | Y37: =C37+B37 -> 1 | AH37: =C37+D37 -> 1 | AL37: =C37+D37 -> 1
A38: =A37+1 -> 34 | B38: =测试题!D40 -> 2 | C38: =测试题!E40 -> 0 | D38: =测试题!F40 -> 0 | G38: =C38+D38 -> 0 | O38: =C38+B38 -> 2
A39: =A38+1 -> 35 | B39: =测试题!D41 -> 2 | C39: =测试题!E41 -> 0 | D39: =测试题!F41 -> 0 | F39: =C39+D39 -> 0 | V39: =C39+B39 -> 2
A40: =A39+1 -> 36 | B40: =测试题!D42 -> 2 | C40: =测试题!E42 -> 0 | D40: =测试题!F42 -> 0 | G40: =C40+D40 -> 0 | J40: =C40+B40 -> 2 | AJ40: =C137+B137 -> 3
A41: =A40+1 -> 37 | B41: =测试题!D43 -> 0 | C41: =测试题!E43 -> 0 | D41: =测试题!F43 -> 3 | AG41: =C41+D41 -> 3 | AJ41: =C41+B41 -> 0
...

Sheet Sheet2
B1: 1、成就
A2: 成就 | B2: 成就主题较强的人大都精力充沛，锲而不舍。他们乐于忙忙碌碌并有所作为。
B3: 你的成就主题说明你的内在动力。它表明你始终渴望有所建树。你感到每一天似乎都从零开始。一天结束时，你必须获得某种有形的成果，如此才能感觉良好。你所谓的“每一天”指的是所有的日子-工作日、周末、休假日。无论你多幺需要歇一天，如果这一天你无所事事，你就会感到不满意。你体内有团烈火在熊熊燃烧。它促使你多做事情，多出成果。完成一项任务后，这火会暂时减弱，但很快重新燃起，迫使你朝一个又一个新的目标不断攀登。你对成就的不懈追求或许缺乏逻辑；甚至漫无边际。然而，它却是永无满足的，并将伴随你一生。作为一名追求成就的人，你必须学会与这种隐隐的不满足感相处。它毕竟不无益处。它给你动力，使你能长久工作而不知疲倦。它不失时机地使你奋起，去迎接新的任务和新的挑战。它为你输入充沛的精力，帮助你为你所领导的班组设定工作进度和业绩指标。它是推动你不断前进的主题。
B4: 2信仰－－自我实现的信徒
A5: 信仰 | B5: 有强烈信仰的人必定拥有某种经久不变的核心价值观，并由此形成明确的生活目标。
B6: 如果你有很强的信仰主题，那你就会持有某些经久不变的核心价值。这些价值因人而异，但你的信仰通常使你关注家庭，乐于助人，甚至追求灵性。无论对己对人，你都珍视责任和伦理。这些核心价值以多种方式影响你的行为。它们赋予你的生活以意义和满足-在你看来，金钱和名望并不完全代表成功。它们为你指明方向，指引你排除生活中的种种引诱和干扰，朝着恒定的目标前进。这种恒定性是你建立所有关系的基础。你的朋友认为你为人可靠；他们会说，“我知道你是什幺立场。”你的信仰为你赢得信任。它还要求你从事与你的价值观相符的工作。你的工作必须有意义；必须“有分量”。因为你受到你的信仰的指引，所以你的工作唯有使你有机会实践自身价值观时才是有意义的。
B8: 3、自信
A9: 自信 | B9: 自信心强的人对自身的能力充满信心。他们有自己的处世准则，做决定时成竹在胸。
B10: 在你的心灵最深处，你对自己的优势充满信心。你深知你是个有能力的人-有能力冒风险，有能力接受新的挑战，有能力提出要求，并且更重要的是，有能力履行诺言。然而不仅如此，由于具有自信的主题，你不仅对自己的能力，而且对自己的判断充满信心。当你观察世界的时候，你深知你的视点与众不同。而由于没有人看问题的角度与你完全一样，你知道没有人能为你作决定；也没有人能告诉你如何去思考。他们能够引导，能够建议，但只有你才是自己生活的主宰。只有你才有权作结论，下决心，去行动。这种权威，这种对自身生活方向的终极负责，并不使你畏惧。相反，它对于你顺乎自然。无论碰到什幺情况，你似乎总能悟出该做什幺。它也许并不适用于所有的人，但它是特定形势下你该做的事情。这一主题给你罩上一层神机妙算的光环。你与许多人不同，从不轻易被别人的论点所左右，无论他们多幺巧言令色。这种自信既可能深藏不露，也可能一目了然，这取决于你的其它主题，。但它根深蒂固，牢不可破。一如舰船的龙骨，它能抵御各种压力，使你把稳航向。
B12: 4、行动
A13: 行动 | B13: 行动主题较强的人能够将想法付诸行动。他们往往缺乏耐心。
B14: “我们什么时候可以开始？”你最爱问这个问题。你急不可耐地要行动。你也许会同意，分析自有它的作用，争辩和讨论有时亦不无真知灼见。但你深知，没有行动，一切皆为空谈。唯有行动才能做事情。唯有行动才能出业绩。一旦作出决定，你就必须行动。别人或许会担忧，“还有些事我们不知道，”但是你不会因此而放慢步伐。如果决定通过城区，你便认定到达目的地的最快途径就是从一个红绿灯走到下一个红绿灯，而不会坐等所有的灯都变绿。此外，在你看来，行动和思考并不互相排斥。事实上，在你的行动才干指引下，你确信最好的办法是干中学。你作出决定，采取行动，检验结果，继而学习进步。在学习的基础上，你决定你未来一步接一步的行动。如果你没有作出反应的对象，你怎么能够进步？你的答案很简单，不能。你必须不断冲锋陷阵。你必须不断走出下一步。否则，你如何保持思维敏锐和耳聪目明？这就是你的底线：你深知评判你的标准不是你的言辞，也不是你的思想，而是你的行动。你丝毫不为此感到畏惧。恰恰相反，你感到快慰。
B16: 5、专注,目标明确－－人生旅程的导游
A17: 专注 | B17: 专注力强的人能够确定方向，贯彻始终，及时调整，矢志不渝。他们先确定重点，再着手行动。
B18: “我正走向何方？”你扪心自问。这一问题每天都萦绕脑际。在专注主题的指引下，你需要一个明确的目的地。没有它，你很快就会对自己的生活和工作一筹莫展。因此，每年，每月，甚至每周，你都做你爱做的事-制定目标。你的目标，无论长期或短期，都有相同的特点。它们都很具体，都能评测，并且都有进度表。这些目标如同罗盘，帮助你确定重点，并进行必要的修正，以保持航向。你的专注主题十分强大，因为它迫使你进行过滤-本能地判断某个行动是否有助于你达到目标；无助于此的便被放弃。你的专注最终迫使你提高效率。无庸讳言，这种模式的另一面是，它使你难以忍受拖延、障碍，甚至迂回，而无论它们多幺引人。这使你成为一名极其可贵的团队成员。当别人开始溜向“有趣的”岔道时，你会及时把他们带回正路。你的专注主题提醒每个人，如果一件事不能帮助大家通往目的地，那它就无关紧要。而如果它无关紧要，那就不值得为它浪费时间。你确保每个人都目不斜视。
B20: 6、追求
A21: 追求 | B21: 追求主题较强的人希望在别人的眼中非同凡响。他们独立性强，渴望被承认。
B22: 你希望在别人的眼中非同凡响。你希望获得真正意义上的“认可”。你希望自己的意见受到重视。你希望出人头地。你希望出名。你尤其希望别人了解和赞赏你的独特优势。你渴望别人赞扬你是一个可信赖和专业化的成功人士。同样，你希望与可信赖和专业化的成功人士交往。如果他们不是这样，你就会推动他们朝此努力，直到成功-否则你就会弃他们而去。你天性独立，希望自己的工作是一种生活方式而不仅仅是一种职业。在工作中，你希望获得充分的自由-按你自己的方式做事的自由。你对自己的渴望感受强烈并付诸行动。为此，你的生活中充斥着你所“需要”，“渴求”，或“热爱”的东西。无论你的目标如何-每个人的目标都与众不同-你的追求主题都将不断将你升高，摆脱平庸，通往卓越。这个主题推动你不断追求。
B24: 7、适应,适应力强－－处变不惊的鬼灵精
A25: 适应 | B25: 适应性强的人倾向于“随大流”。他们活在“当前”，接受现实，随遇而安。
B26: 你生活在当前。你不把未来视为固定的目的地。相反，你认为未来是你在现有选择的基础上创造出来的。因此，你通过选择逐一发现你的未来。这并不意味着你没有计划。你很可能有。但你的适应主题使你能够自愿地对眼前需求作出反应，即使此举使你偏离原有计划。你与有的人不同，并不讨厌突如其来的要求或出乎意料的曲折。你对此有料在先，它是不可避免的。事实上，在某种意义上，你期待它们发生。你本质上是一个非常灵活的人，即使工作的不同需求把你东拉西扯，你仍能保持高效率。 适应主题的人表现为高度的灵活性。不仅面对变化可以保持高效率，而且事实上喜欢应对不断变化的情况，甚至自己都会去制造变化。具备适应主题的人对长远计划通常是不屑一顾的。很对很对啊。我不仅不喜欢做长远计划，连今天出门是去看电影还是逛公园一般也定不下来。要不是为了考虑到其它人，我大概会乐于在每一个最后时刻改变主意。对于某些人来讲，这种“脚踩西瓜皮”的秉性几乎无法忍受，但是以后我要告诉他们：这叫做“适应”！Adaptive，那可是如今 IT 界最时髦的词汇，包括我所属的那个大公司都以 Adaptive 为核心理念，所以我看公司以后就干脆把我当最优质产品卖出去算了——一个能“适应”的好货色。
B28: 8、纪律
A29: 纪律 | B29: 纪律性强的人做事井然有序，有章有法。他们建立规程，遵章守纪。
B30: 你的世界必须可以预测，必须井井有条，规划有序。因此，你本能地将你的世界规范化。你建立常规，制定时间表，规定完成任务的日期。你把长期项目划分为一系列具体的短期计划，然后锲而不舍地逐一实施。你并不一定整洁有序，但你的确要求精确。面对生活中内在的混乱，你需要建立控制。常规、时间表、规范-这一切都有助于建立控制感。别人由于缺乏这种纪律主题，有时可能厌恶你建立秩序的需求。但这未必导致冲突。你必须了解，并非人人都象你一样渴求预测-他们自有其做事之道。同样，你也可以帮助他们理解、甚至赞赏你对规思维 思维能力较强的人的最大特点是长于思考。他们勤于自省，敏于探讨。 范的需求。你讨厌意外，憎恶失误，建立常规，注重细节-所有这些无须被视为意欲束缚别人，而应被视为你的一种本能的方法，旨在摈除生活的诸多诱惑，确保进步和效益。
B32: 9、排难
A33: 排难 | B33: 排除故障的行家里手善于发现问题并解决问题。
B34: 你热衷于排忧解难。其它人遇到新困难往往一筹莫展，而你却干劲倍增。面对分析症状、判断问题和解决问题的挑战，你无比兴奋。你可能会喜欢实际的、抽象的、或个人的问题。你可能会寻找你过去多次遇到并自信能解决的问题。或许当你遇到复杂而陌生的问题时最为激奋。你的具体偏好将取决于你的其它优势和经历。但可以肯定的是，你喜欢手到病除。判断故障，排除问题，起死回生，使你其乐无穷。你本能地感到，没有你的介入，这个东西-这部机器、这个人、这家公司很可能会停转。你修好了它。救活了它。使它重燃生命之火。或者用你自己的话说，你拯救了它。
B36: 10、回顾，继往开来－－现在与未来的过客:
A37: 回顾 | B37: 回顾主题较强的人喜欢追溯从前。他们通过揣摩过去来了解当前。
B38: 你往回看。你往回看是为了了解当前。你往回看是为了预测未来。你想知道这一切都是如何开始的，所以你购买历史书和人物传记，并且向熟人打听其过去的经历。你往回看，因为答案可以在过去找到。从你的制高点看去，当前变动无常，杂乱无章。唯有回首以往-回到策划之初-当前才重归平稳。以往是一个简明的时代，一个描画蓝图的时代。你回顾以往，目睹蓝图浮现，继而重归初衷。这些蓝图和初衷后来被装饰得面目全非，无从辨认-但是你的回顾主题使它们原形再现。这一认识使你充满信心。你排除了干扰，在了解事物内涵的基础上明智决策。由于了解同事们的来龙去脉，你就能更好地与其合作。并且，由于你看到未来的种子播撒在过去，反而更加明察未来。面对新人和新形势，你需要一些时间来适应。但你必须给自己留出这些时间。你必须迫使自己问这些问题。你必须让蓝图再现，因为无论情况如何，如果你未见蓝图，你就不可能尽你所能。
B39: 11、公平,讲究公平－－平等的守护者
A40: 公平 | B40: 公平心强的人深知应平等待人。他们确立并坚持这一准则，即公平地对待每一个人。
B41: 平衡对你很重要。你深知需要公平待人，无论其社会地位如何。因此，你不希望天平过于倒向任何个人。你确信这将导致自私自利和个人至上，使某些人凭借关系或背景，或通过贿赂而获得不公平的优势。你对此深恶痛绝。你自视抵御这种倾向的卫士。与这种裙带世界截然相反，你深信只有在规则明确而人人适用的恒定的环境中，才能发挥每个人的最大潜能。因为在这样的环境中，每个人都了解对其的期待，一切都可以预测并不偏不倚。一切都公平。在这里，每个人将有平等的机会施展才华。
B43: 12、审慎,深思熟虑－－步步为营的沉思者
A44: 审慎 | B44: 他们每做一个决定均慎之又慎，并设想所有的困难。
B45: 你总是小心翼翼、保持高度警戒、注重隐私。你知道世事难料。尽管一切看似井然有序，你仍觉得危机处处。你不否认危险的存在，反而一一挑明危险所在。如此一来，每种危险都能加以鉴定、评估，终能减轻其危险性。因此，你是一个相当严肃的人，以保留的态度看待人生。例如，你喜欢事先计画，预期可能出错之处。你择友谨慎，只跟特定人士谈个人的隐私。你不会过度赞扬或肯定别人，以免遭人误会。如果有人因为你不像其它人一样感情外露而不喜欢你，你也觉得无所谓。对你而言，生命不是一场比人气的竞赛。生命犹如地雷区，依个人抉择，有人可以毫不在乎地跑过去，但是你会找出危险、衡量相关冲击，然后小心踏出步伐，缓步前进。
B47: 13、前瞻
A48: 前瞻 | B48: 对于有较强前瞻力的人而言，未来令人心潮澎湃。他们用对未来的憧憬激励周围的人。
B49: “如果这样，那该多好？”你是个喜欢遥望天际的人。未来使你着迷。未来如同墙壁上的投影，在你眼中维妙维肖。这幅细致入微的图画催你奋进，奔向明天。虽然未来图景的具体内容取决于你的其它优势和兴趣-更好的产品，更好的队伍，更好的生活，或更好的世界-但它将永远给你以灵感。你是一个幻想家，能看到未来的种种可能，并珍视这样的想象。当现实使你一筹莫展，而你周围的人又过于世俗时，你就会唤起对未来的憧憬，继而精力倍增，同时振奋别人。事实上，人们往往期待你描述对未来的种种遐想。他们希望看到一幅画卷，来提高他们的眼界，继而燃起激情。你能为他们描绘这幅画卷。不断实践。字斟句酌。越生动越好。人们将拥抱你所带来的希望。
B51: 14、搜集－－嗜好收藏－－惜物如命的收藏家:
...

Sheet 结果
A1: =IF(结!A1="","",结!A1) | B1: =IF(结!B1="","",结!B1) | C1: =IF(结!C1="","",结!C1) | D1: =IF(结!D1="","",结!D1) | E1: =IF(结!E1="","",结!E1) | F1: =IF(结!F1="","",结!F1) | G1: =IF(结!G1="","",结!G1) | H1: =IF(结!H1="","",结!H1) | ... K1: =IF(结!K1="","",结!K1)
A2: =IF(结!A2="","",结!A2) | B2: =IF(结!B2="","",结!B2) -> 欢迎使用Excel《盖洛普优势识别器》测试系统 | J2: =IF(结!J2="","",结!J2) | K2: =IF(结!K2="","",结!K2)
A3: =IF(结!A3="","",结!A3) | B3: =IF(结!B3="","",结!B3) | C3: =IF(结!C3="","",结!C3) | D3: =IF(结!D3="","",结!D3) | E3: =IF(结!E3="","",结!E3) | F3: =IF(结!F3="","",结!F3) | G3: =IF(结!G3="","",结!G3) | H3: =IF(结!H3="","",结!H3) | ... K3: =IF(结!K3="","",结!K3)
A4: =IF(结!A4="","",结!A4) | B4: =IF(结!B4="","",结!B4) | C4: =IF(结!C4="","",结!C4) -> 测试结果： | D4: =IF(结!D4="","",结!D4) | E4: =IF(结!E4="","",结!E4) | F4: =IF(结!F4="","",结!F4) | G4: =IF(结!G4="","",结!G4) | H4: =IF(结!H4="","",结!H4) | ... K4: =IF(结!K4="","",结!K4)
A5: =IF(结!A5="","",结!A5) | B5: =IF(结!B5="","",结!B5) | C5: =IF(结!C5="","",结!C5) -> 答题的过程中以下各项优势均随着答题情况不断变化， 答题完成后的排序就是您性格优势的排列顺序。 | D5: =IF(结!D5="","",结!D5) | E5: =IF(结!E5="","",结!E5) | F5: =IF(结!F5="","",结!F5) | G5: =IF(结!G5="","",结!G5) | H5: =IF(结!H5="","",结!H5) | ... K5: =IF(结!K5="","",结!K5)
A6: =IF(结!A6="","",结!A6) | B6: =IF(结!B6="","",结!B6) | C6: =IF(结!C6="","",结!C6) | D6: =IF(结!D6="","",结!D6) | E6: =IF(结!E6="","",结!E6) | F6: =IF(结!F6="","",结!F6) | G6: =IF(结!G6="","",结!G6) | H6: =IF(结!H6="","",结!H6) | ... K6: =IF(结!K6="","",结!K6)
A7: =IF(结!A7="","",结!A7) | B7: =IF(结!B7="","",结!B7) | C7: =IF(结!C7="","",结!C7) -> NO | D7: =IF(结!D7="","",结!D7) -> 优势 | E7: =IF(结!E7="","",结!E7) -> 得分 | F7: =IF(结!F7="","",结!F7) -> NO | G7: =IF(结!G7="","",结!G7) -> 优势 | H7: =IF(结!H7="","",结!H7) -> 得分 | ... K7: =IF(结!K7="","",结!K7)
A8: =IF(结!A8="","",结!A8) | B8: =IF(结!B8="","",结!B8) | C8: =IF(结!C8="","",结!C8) -> 1 | D8: =IF(结!D8="","",结!D8) -> 战略 | E8: =IF(结!E8="","",结!E8) -> 2.25 | F8: =IF(结!F8="","",结!F8) -> 18 | G8: =IF(结!G8="","",结!G8) -> 个别 | H8: =IF(结!H8="","",结!H8) -> 1 | ... K8: =IF(结!K8="","",结!K8)
A9: =IF(结!A9="","",结!A9) | B9: =IF(结!B9="","",结!B9) | C9: =IF(结!C9="","",结!C9) -> 2 | D9: =IF(结!D9="","",结!D9) -> 思维 | E9: =IF(结!E9="","",结!E9) -> 2.2 | F9: =IF(结!F9="","",结!F9) -> 19 | G9: =IF(结!G9="","",结!G9) -> 纪律 | H9: =IF(结!H9="","",结!H9) -> 1 | ... K9: =IF(结!K9="","",结!K9)
A10: =IF(结!A10="","",结!A10) | B10: =IF(结!B10="","",结!B10) | C10: =IF(结!C10="","",结!C10) -> 3 | D10: =IF(结!D10="","",结!D10) -> 理念 | E10: =IF(结!E10="","",结!E10) -> 2.1666667 | F10: =IF(结!F10="","",结!F10) -> 20 | G10: =IF(结!G10="","",结!G10) -> 竞争 | H10: =IF(结!H10="","",结!H10) -> 1 | ... K10: =IF(结!K10="","",结!K10)
A11: =IF(结!A11="","",结!A11) | B11: =IF(结!B11="","",结!B11) | C11: =IF(结!C11="","",结!C11) -> 4 | D11: =IF(结!D11="","",结!D11) -> 学习 | E11: =IF(结!E11="","",结!E11) -> 1.875 | F11: =IF(结!F11="","",结!F11) -> 21 | G11: =IF(结!G11="","",结!G11) -> 适应 | H11: =IF(结!H11="","",结!H11) -> 0.94444444 | ... K11: =IF(结!K11="","",结!K11)
A12: =IF(结!A12="","",结!A12) | B12: =IF(结!B12="","",结!B12) | C12: =IF(结!C12="","",结!C12) -> 5 | D12: =IF(结!D12="","",结!D12) -> 前瞻 | E12: =IF(结!E12="","",结!E12) -> 1.75 | F12: =IF(结!F12="","",结!F12) -> 22 | G12: =IF(结!G12="","",结!G12) -> 回顾 | H12: =IF(结!H12="","",结!H12) -> 0.93333333 | ... K12: =IF(结!K12="","",结!K12)
A13: =IF(结!A13="","",结!A13) | B13: =IF(结!B13="","",结!B13) | C13: =IF(结!C13="","",结!C13) -> 6 | D13: =IF(结!D13="","",结!D13) -> 统率 | E13: =IF(结!E13="","",结!E13) -> 1.7333333 | F13: =IF(结!F13="","",结!F13) -> 23 | G13: =IF(结!G13="","",结!G13) -> 完美 | H13: =IF(结!H13="","",结!H13) -> 0.88235294 | ... K13: =IF(结!K13="","",结!K13)
A14: =IF(结!A14="","",结!A14) | B14: =IF(结!B14="","",结!B14) | C14: =IF(结!C14="","",结!C14) -> 7 | D14: =IF(结!D14="","",结!D14) -> 统筹 | E14: =IF(结!E14="","",结!E14) -> 1.6666667 | F14: =IF(结!F14="","",结!F14) -> 24 | G14: =IF(结!G14="","",结!G14) -> 搜集 | H14: =IF(结!H14="","",结!H14) -> 0.88235294 | ... K14: =IF(结!K14="","",结!K14)
... A25: =IF(结!A25="","",结!A25) | B25: =IF(结!B25="","",结!B25) | C25: =IF(结!C25="","",结!C25) | D25: =IF(结!D25="","",结!D25) | E25: =IF(结!E25="","",结!E25) | F25: =IF(结!F25="","",结!F25) | G25: =IF(结!G25="","",结!G25) | H25: =IF(结!H25="","",结!H25) | ... K25: =IF(结!K25="","",结!K25)
A26: =IF(结!A26="","",结!A26) -> 180 | B26: =IF(结!B26="","",结!B26) -> 由以上结果可以看出，您的优势为： | I26: =IF(结!I26="","",结!I26) | J26: =IF(结!J26="","",结!J26) | K26: =IF(结!K26="","",结!K26)
A27: =IF(结!A27="","",结!A27) | B27: =IF(结!B27="","",结!B27) -> 1 | C27: =IF(结!C27="","",结!C27) -> 战略 | D27: =IF(结!D27="","",结!D27) -> 战略主题较强的人足智多谋。针对不同的方案，能迅速找出相关的模式及结果。 | E27: =IF(结!E27="","",结!E27) | F27: =IF(结!F27="","",结!F27) | G27: =IF(结!G27="","",结!G27) | H27: =IF(结!H27="","",结!H27) | ... K27: =IF(结!K27="","",结!K27)
A28: =IF(结!A28="","",结!A28) | B28: =IF(结!B28="","",结!B28) | C28: =IF(结!C28="","",结!C28) -> 战略主题使你能够透过日常琐碎，寻找前进的捷径。它不是一种可以教授的技能，而是一种与众不同的思维方式，一种独特的世界观。有了这种世界观，当别人被复杂的事物所迷惑时，你却能识别其中的规律。你将规律牢记在心，尝试各种不同的方案，不断问自己“如果发生这种情况会怎样？如果发生那种情况会怎样？”这些不断出现的问题帮助你预防不测。如此你便能够精确判断潜在的障碍。你看清各条路径的走向，就能进行筛选。你筛去死路。你筛去直通屏障的路线。你筛去通往混乱和迷茫的路线。你不断筛选，直到你选定一条路线-这就是你的战略。有了战略武装，你开始出击。这就是你的战略主题的运作模式：“倘若……会怎样？”筛选，出击。 | D28: =IF(结!D28="","",结!D28) | E28: =IF(结!E28="","",结!E28) | F28: =IF(结!F28="","",结!F28) | G28: =IF(结!G28="","",结!G28) | H28: =IF(结!H28="","",结!H28) | ... K28: =IF(结!K28="","",结!K28)
A29: =IF(结!A29="","",结!A29) | B29: =IF(结!B29="","",结!B29) -> 2 | C29: =IF(结!C29="","",结!C29) -> 思维 | D29: =IF(结!D29="","",结!D29) -> 思维能力较强的人的最大特点是长于思考。他们勤于自省，敏于探讨。 | E29: =IF(结!E29="","",结!E29) | F29: =IF(结!F29="","",结!F29) | G29: =IF(结!G29="","",结!G29) | H29: =IF(结!H29="","",结!H29) | ... K29: =IF(结!K29="","",结!K29)
A30: =IF(结!A30="","",结!A30) | B30: =IF(结!B30="","",结!B30) | C30: =IF(结!C30="","",结!C30) -> 你喜欢思考。你喜欢思想活动。你喜欢锻炼你的大脑“肌肉”，把它们四面抻扯。这种对思想活动的需求有可能是专注的，专注的焦点取决于你的其它优势。例如，你可能努力解决一个问题，或酝酿一个创意，或了解另一个人的感受。另一方面，这种思维活动很可能漫无边际。思维的主题并不一定限定你思考的具体内容。它只是说你喜欢思考。你是一个喜欢独处的人，因为这样你才能沉思冥想。你性格内向。在某种意义上，你是自己最好的伴侣，因为你扪心自问，并在自己身上测试答案。当你把自己的实际作为与你所思考的所有想法相比时，你的这种自省可能会使你略为不满。但此种自省也可能导致你关注现实问题，例如当日所发生的事件，或你准备进行的一场谈话。无论它把你引向何方，这种不停的思考是你生活中的一个固定内容。 | D30: =IF(结!D30="","",结!D30) | E30: =IF(结!E30="","",结!E30) | F30: =IF(结!F30="","",结!F30) | G30: =IF(结!G30="","",结!G30) | H30: =IF(结!H30="","",结!H30) | ... K30: =IF(结!K30="","",结!K30)
A31: =IF(结!A31="","",结!A31) | B31: =IF(结!B31="","",结!B31) -> 3 | C31: =IF(结!C31="","",结!C31) -> 理念 | D31: =IF(结!D31="","",结!D31) -> 他们痴迷于各种理念，能够从貌似毫无关联的现象中找出其相互联系。 | E31: =IF(结!E31="","",结!E31) | F31: =IF(结!F31="","",结!F31) | G31: =IF(结!G31="","",结!G31) | H31: =IF(结!H31="","",结!H31) | ... K31: =IF(结!K31="","",结!K31)
A32: =IF(结!A32="","",结!A32) | B32: =IF(结!B32="","",结!B32) | C32: =IF(结!C32="","",结!C32) -> 你为理念而痴迷。什幺是理念？理念就是概念，就是对大部分事件的最合理的解释。当你透过复杂的表层，发现一个精彩而简明的概念，继而解释事物的本质时，你会喜不自胜。理念是一种关联。你的头脑总在寻找关联；因此，当表面截然不同的现象被某个不起眼的纽带联系在一起时，你会感到新奇。一个理念是对习以为常的挑战的全新见解。你乐于将我们熟知的世界转一个圈，让我们从一个陌生但充满新意的角度看它。你喜爱所有这些理念。因为它们深刻。因为它们新颖。因为它们能正本清源。因为它们引发争论。因为它们怪诞。由于所有这些原因，每当你产生一个新理念时，你都为之一振。别人可能视你为锐意创新、标新立异、富于理性或聪明过人。也许这些你都是。谁能说得准呢？你确信无疑的是理念使你激动不已。而大多数日子里，这就足够了。 | D32: =IF(结!D32="","",结!D32) | E32: =IF(结!E32="","",结!E32) | F32: =IF(结!F32="","",结!F32) | G32: =IF(结!G32="","",结!G32) | H32: =IF(结!H32="","",结!H32) | ... K32: =IF(结!K32="","",结!K32)
A33: =IF(结!A33="","",结!A33) | B33: =IF(结!B33="","",结!B33) -> 4 | C33: =IF(结!C33="","",结!C33) -> 学习 | D33: =IF(结!D33="","",结!D33) -> 学习能力强的人有旺盛的求知欲，渴望不断提高自我。尤其令他们激动的，是求知的过程而非结果。 | E33: =IF(结!E33="","",结!E33) | F33: =IF(结!F33="","",结!F33) | G33: =IF(结!G33="","",结!G33) | H33: =IF(结!H33="","",结!H33) | ... K33: =IF(结!K33="","",结!K33)
A34: =IF(结!A34="","",结!A34) | B34: =IF(结!B34="","",结!B34) | C34: =IF(结!C34="","",结!C34) -> 你热爱学习。你最感兴趣的题目取决于你的其它主题和经历。但无论是什幺题目，你总是受到学习过程的吸引。过程，而不是内容或结果，最使你兴奋。从无知到熟练的扎实而执着的进程使你精力倍增。入门的快感；初学者背诵或实践学到的内容；掌握一门新技术而日益增强的信心-这些学习的过程深深吸引着你。你对学习的激情促使你参加各种成人教程-太极拳、外语、钢琴、舞蹈或电脑培训班等等。它使你能在变动无常的环境中应付自如，无论是分配你完成一个应急项目，还是反复要求你在短时间内成为某个新题目的行家。学习主题并不一定意味着你力图成为某个专题的专家，或追求伴随某种专业或学术头衔的荣耀。相比之下，更重要的是学习的“路程”，而不是具体结果。 | D34: =IF(结!D34="","",结!D34) | E34: =IF(结!E34="","",结!E34) | F34: =IF(结!F34="","",结!F34) | G34: =IF(结!G34="","",结!G34) | H34: =IF(结!H34="","",结!H34) | ... K34: =IF(结!K34="","",结!K34)
A35: =IF(结!A35="","",结!A35) | B35: =IF(结!B35="","",结!B35) -> 5 | C35: =IF(结!C35="","",结!C35) -> 前瞻 | D35: =IF(结!D35="","",结!D35) -> 对于有较强前瞻力的人而言，未来令人心潮澎湃。他们用对未来的憧憬激励周围的人。 | E35: =IF(结!E35="","",结!E35) | F35: =IF(结!F35="","",结!F35) | G35: =IF(结!G35="","",结!G35) | H35: =IF(结!H35="","",结!H35) | ... K35: =IF(结!K35="","",结!K35)
A36: =IF(结!A36="","",结!A36) | B36: =IF(结!B36="","",结!B36) | C36: =IF(结!C36="","",结!C36) -> “如果这样，那该多好？”你是个喜欢遥望天际的人。未来使你着迷。未来如同墙壁上的投影，在你眼中维妙维肖。这幅细致入微的图画催你奋进，奔向明天。虽然未来图景的具体内容取决于你的其它优势和兴趣-更好的产品，更好的队伍，更好的生活，或更好的世界-但它将永远给你以灵感。你是一个幻想家，能看到未来的种种可能，并珍视这样的想象。当现实使你一筹莫展，而你周围的人又过于世俗时，你就会唤起对未来的憧憬，继而精力倍增，同时振奋别人。事实上，人们往往期待你描述对未来的种种遐想。他们希望看到一幅画卷，来提高他们的眼界，继而燃起激情。你能为他们描绘这幅画卷。不断实践。字斟句酌。越生动越好。人们将拥抱你所带来的希望。 | D36: =IF(结!D36="","",结!D36) | E36: =IF(结!E36="","",结!E36) | F36: =IF(结!F36="","",结!F36) | G36: =IF(结!G36="","",结!G36) | H36: =IF(结!H36="","",结!H36) | ... K36: =IF(结!K36="","",结!K36)
A37: =IF(结!A37="","",结!A37) | B37: =IF(结!B37="","",结!B37) | C37: =IF(结!C37="","",结!C37) | D37: =IF(结!D37="","",结!D37) | E37: =IF(结!E37="","",结!E37) | F37: =IF(结!F37="","",结!F37) | G37: =IF(结!G37="","",结!G37) | H37: =IF(结!H37="","",结!H37) | ... K37: =IF(结!K37="","",结!K37)
A38: =IF(结!A38="","",结!A38) | B38: =IF(结!B38="","",结!B38) | C38: =IF(结!C38="","",结!C38) | D38: =IF(结!D38="","",结!D38) | E38: =IF(结!E38="","",结!E38) | F38: =IF(结!F38="","",结!F38) | G38: =IF(结!G38="","",结!G38) | H38: =IF(结!H38="","",结!H38) | ... K38: =IF(结!K38="","",结!K38)
... A81: =IF(结!A81="","",结!A81) | B81: =IF(结!B81="","",结!B81) | C81: =IF(结!C81="","",结!C81) | D81: =IF(结!D81="","",结!D81) | E81: =IF(结!E81="","",结!E81) | F81: =IF(结!F81="","",结!F81) | G81: =IF(结!G81="","",结!G81) | H81: =IF(结!H81="","",结!H81) | ... K81: =IF(结!K81="","",结!K81)
